<mujoco model="addverb_heal">
   <option gravity="0 0 -9.81" />
   <compiler angle="radian" 
   inertiafromgeom="false" 
   discardvisual="false" 
   meshdir="../heal_meshes/" />

   <statistic center="0.3 0 0.4" extent="1.5"/>

   <asset>
      <texture type="skybox" builtin="gradient" rgb1="0.3 0.5 0.7" rgb2="0 0 0" width="512" height="3072"/>
      <texture type="2d" name="groundplane" builtin="checker" mark="edge" rgb1="0.2 0.3 0.4" rgb2="0.1 0.2 0.3"
         markrgb="0.8 0.8 0.8" width="300" height="300"/>
      <material name="groundplane" texture="groundplane" texuniform="true" texrepeat="5 5" reflectance="0.2"/>
      
      <material name="arm" rgba="0.75294 0.75294 0.75294 0"/>
      
      <mesh name="base_link" file="base_link.STL" />
      <mesh name="link1" file="link_1.STL" />
      <mesh name="link2" file="link_2.STL" />
      <mesh name="link3" file="link_3.STL" />
      <mesh name="link4" file="link_4.STL" />
      <mesh name="link5" file="link_5.STL" />
      <mesh name="end_effector" file="end_effector.STL" />
   </asset>

   <default>
      <default class="my_robot">
         <general gaintype="fixed" biastype="affine" gainprm="200" biasprm="0 -200 0"/>
      </default>
   </default>

   <worldbody>
      <light pos="0 0 1.5" dir="0 0 -1" directional="true"/>
      <geom name="floor" size="0 0 0.05" type="plane" material="groundplane"/>
      <camera name="scene_3d_view" pos="1 1 1" zaxis="-0 -1 -1"/>

      <!-- Mocap target for IK -->
      <body name="target" pos="0.0 0 0" quat="0 0 0 1" mocap="true">
         <geom name="target_geom" type="box" size=".05 .05 .05" contype="0" conaffinity="0" rgba=".6 .3 .3 .2"/>
      </body>

      <!-- Arm -->
      <body name="base_link" pos="0.0 0 0" euler="0 0 0">
         <geom name="base_link_visual" type="mesh" mesh="base_link" group="1" contype="0" conaffinity="0"/>
         <geom name="base_link_collision" type="mesh" mesh="base_link" group="0" contype="0" conaffinity="0" material="arm"/>
         <body name="link_1" pos="0 0 0.171">
            <inertial pos="-12.54E-03 -0.04E-03 111.27E-03" 
                      quat="0.704455 -0.0304055 0.0162858 0.70891" 
                      mass="7.92" diaginertia="0.00490984 0.00426023 0.00389513" />
            <joint name="joint_1" pos="0 0 0" axis="0 0 1" range="-3.14159 3.14159" damping="100" frictionloss="0.1" actuatorfrcrange="-10000 10000" />
            <geom name="link_1_visual" type="mesh" mesh="link1" group="1" contype="0" conaffinity="0" material="arm"/>
            <geom name="link_1_collision" type="mesh" mesh="link1" group="0"/>
            
            <body name="link_2" pos="0 0.0875 0.1498" quat="0.707105 0.707108 0 0">
               <inertial pos="-0.00017021 0.1561 -0.016973" 
                         quat="0.499892 0.50026 -0.499813 0.500035" 
                         mass="1.24" diaginertia="0.0097684 0.0086581 0.0014536" />
               <joint name="joint_2" pos="0 0 0" axis="0 0 -1" range="-3.14159 3.14159" damping="100" frictionloss="0.1" actuatorfrcrange="-10000 10000" />
               <geom name="link_2_visual" type="mesh" mesh="link2" group="1" contype="0" conaffinity="0" material="arm"/>
               <geom name="link_2_collision" type="mesh" mesh="link2" group="0"/>
               
               <body name="link_3" pos="0 0.3 0" euler="0 0 -1.57">
                  <inertial pos="-7.5516e-07 0 0.073251" 
                            quat="0.495149 0.509997 -0.506629 0.487912" 
                            mass="5.57" diaginertia="0.0048786 0.00425304 0.00369796" />
                  <joint name="joint_3" pos="0 0 0" axis="0 0 1" range="-3.14159 3.14159" damping="100" frictionloss="0.1" actuatorfrcrange="-10000 10000" />
                  <geom name="link_3_visual" type="mesh" mesh="link3" group="1" contype="0" conaffinity="0" material="arm"/>
                  <geom name="link_3_collision" type="mesh" mesh="link3" group="0"/>

                  <body name="link_4" pos="0 0.1593 0.0875" euler="-1.57 0 0">
                     <inertial pos="1.3303e-05 0.06 0.10412" 
                               quat="0.313668 0.63349 -0.634256 0.313086" 
                               mass="1.9" diaginertia="0.00162547 0.0014257 0.00104183" />
                     <joint name="joint_4" pos="0 0 0" axis="0 0 1" range="-3.14159 3.14159" damping="100"  frictionloss="0.1" actuatorfrcrange="-10000 10000" />
                     <geom name="link_4_visual" type="mesh" mesh="link4" group="1" contype="0" conaffinity="0" material="arm"/>
                     <geom name="link_4_collision" type="mesh" mesh="link4" group="0"/>

                     <body name="link_5" pos="0 0.03185 0.16105" euler="0.50951 0 1.57">
                        <inertial pos="-5.6194e-05 -0.046 0.059696" 
                                  quat="0.457117 0.537094 0.438555 0.556994" 
                                  mass="1.78" diaginertia="0.000913478 0.000827593 0.000774169" />
                        <joint name="joint_5" pos="0 0 0" axis="0 0 1" range="-3.14159 3.14159" damping="100"  frictionloss="0.1" actuatorfrcrange="-10000 10000" />
                        <geom name="link_5_visual" type="mesh" mesh="link5" group="1" contype="0" conaffinity="0" material="arm"/>
                        <geom name="link_5_collision" type="mesh" mesh="link5" group="0"/>

                        <body name="end_effector" pos="0 -0.1227 0.0654" quat="0.707105 0.707108 0 0">
                           <body name="right_hand" pos="0.0 0.0 0.0" quat="1 0 0 0">
                              <camera mode="fixed" name="right_eye_in_hand" pos="0.05 0 0" quat="0.5 0.5 -0.5 -0.5" fovy="75"/>
                           </body>
                           <inertial pos="7.0245e-06 -0.00022138 -0.016847" 
                                     quat="-0.0128774 0.707029 0.00995758 0.706998" 
                                     mass="0.001" diaginertia="0.000326122 0.000191249 0.000189678" />
                           <joint name="joint_6" pos="0 0 0" axis="0 0 -1" range="-3.14159 3.14159" damping="100"  frictionloss="0.1" actuatorfrcrange="-10000 10000" />
                           <site name="attachment_site" pos="0 0 0" size="0.01" rgba="1 0.3 0.3 1" group="2"/>
                           <geom name="end_effector_visual" type="mesh" mesh="end_effector" group="1" contype="0" conaffinity="0" material="arm"/>
                           <geom name="end_effector_collision" type="mesh" mesh="end_effector" group="0"/>
                        </body>
                     </body>
                  </body>   
               </body>
            </body>
         </body>
      </body>
   </worldbody>

   <!-- Actuators -->
   <actuator>
      <general name="turret" joint="joint_1" class="my_robot"/>
      <general name="shoulder" joint="joint_2" class="my_robot"/>
      <general name="elbow" joint="joint_3" class="my_robot"/>
      <general name="wrist_1" joint="joint_4" class="my_robot"/>
      <general name="wrist_2" joint="joint_5" class="my_robot"/>
      <general name="wrist_3" joint="joint_6" class="my_robot"/>
   </actuator>

   <!-- Keyframe for Home Position -->
   <keyframe>
      <key name="home" qpos="0 0 0 0 0 0" ctrl="0 0 0 0 0 0"/>
   </keyframe>

</mujoco>



<!-- <?xml version="1.0"?>
<mujoco model="heal_single_arm">
 <option gravity="0 0 -9.18" />
 <compiler angle="radian" inertiafromgeom="false" discardvisual="false" meshdir="../heal_meshes/" />
 <statistic center="0.3 0 0.4" extent="1.5"/>
 
 <asset>
 <texture type="skybox" builtin="gradient" rgb1="0.3 0.5 0.7" rgb2="0 0 0" width="512" height="3072"/>
 <texture type="2d" name="groundplane" builtin="checker" mark="edge" rgb1="0.2 0.3 0.4" rgb2="0.1 0.2 0.3"
 markrgb="0.8 0.8 0.8" width="300" height="300"/>
 <material name="groundplane" texture="groundplane" texuniform="true" texrepeat="5 5" reflectance="0.2"/>
 
 <mesh name="base_link" file="base_link.STL"/>
 <mesh name="link1" file="link_1.STL"/>
 <mesh name="link2" file="link_2.STL"/>
 <mesh name="link3" file="link_3.STL"/>
 <mesh name="link4" file="link_4.STL"/>
 <mesh name="link5" file="link_5.STL"/>
 <mesh name="end_effector" file="end_effector.STL"/>
 
 <material name="green_material" rgba="0.2 0.8 0.2 1"/>
 <material name="grey_material" rgba="0.75294 0.75294 0.75294 1"/>
 <material name="light_gray" rgba="0.8 0.8 0.8 1"/> <!-- Added missing material -->
 <material name="black" rgba="0.1 0.1 0.1 1"/> <!-- Added missing material -->
 <material name="collision_visual" rgba="0.8 0.2 0.2 0.3"/>
 </asset>

 <default>
 <default class="visual">
 <geom type="mesh" contype="0" conaffinity="0" group="2"/>
 </default>
 <default class="collision">
 <geom contype="1" conaffinity="1" group="3" material="collision_visual"/>
 </default>
 </default>

 <worldbody>
 <light pos="0 0 1.5" dir="0 0 -1" directional="true"/>
 <camera name="scene_3d_view" pos="1 1 1" zaxis="-0 -1 -1"/>

 <body name="left_base_link" pos="0.2 0 0" euler="0 0 1.5708">
 <geom class="visual" type="mesh" mesh="base_link" material="grey_material"/>
 <!-- Base link collision geoms -->
 <geom class="collision" type="box" size="0.2 0.2 0.05" pos="0 0 0"/>
 <geom class="collision" type="cylinder" size="0.15 0.1" pos="0 0 0.1" euler="1.5708 0 0"/>
 <geom class="collision" type="box" size="0.1 0.1 0.02" pos="-0.15 0 0.05"/>
 <geom class="collision" type="box" size="0.1 0.1 0.02" pos="0.15 0 0.05"/>
 <inertial mass="10" pos="0 0 0" diaginertia="0.1 0.1 0.1"/>

 <body name="left_link_1" pos="0 0 0.171">
 <joint name="left_joint_1" pos="0 0 0" axis="0 0 1" range="-3.14159 3.14159" damping="55"/>
 <geom class="visual" type="mesh" mesh="link1" material="green_material"/>
 <!-- Link 1 collision geoms -->
 <geom class="collision" type="capsule" size="0.08" fromto="0 0 -0.05 0 0 0.2"/>
 <geom class="collision" type="sphere" size="0.09" pos="0 0 0.075"/>
 <geom class="collision" type="box" size="0.07 0.07 0.02" pos="0 0.05 0.1"/>
 <geom class="collision" type="box" size="0.07 0.07 0.02" pos="0 -0.05 0.1"/>
 <inertial mass="10" pos="0 0 0" diaginertia="0.1 0.1 0.1"/>

 <body name="left_link_2" pos="0 0.0875 0.1498" quat="0.707105 0.707108 0 0">
 <joint name="left_joint_2" pos="0 0 0" axis="0 0 -1" range="-3.14159 3.14159" damping="55"/>
 <geom class="visual" type="mesh" mesh="link2" material="green_material"/>
 <!-- Link 2 collision geoms -->
 <geom class="collision" type="capsule" size="0.07" fromto="0 -0.1 0 0 0.2 0"/>
 <geom class="collision" type="sphere" size="0.08" pos="0 0.05 0"/>
 <geom class="collision" type="sphere" size="0.08" pos="0 -0.05 0"/>
 <geom class="collision" type="box" size="0.06 0.06 0.06" pos="0 0.15 0"/>
 <geom class="collision" type="box" size="0.06 0.06 0.06" pos="0 -0.1 0"/>
 <inertial mass="10" pos="0 0 0" diaginertia="0.1 0.1 0.1"/>

 <body name="left_link_3" pos="0 0.3 0" euler="0 0 -1.57">
 <joint name="left_joint_3" pos="0 0 0" axis="0 0 1" range="-3.14159 3.14159" damping="55"/>
 <geom class="visual" type="mesh" mesh="link3" material="green_material"/>
 <!-- Link 3 collision geoms (detailed like KUKA model) -->
 <geom class="collision" size="0.075" pos="0 0 0.0355"/>
 <geom class="collision" size="0.06" pos="0.01 0.023 0.0855"/>
 <geom class="collision" size="0.055" pos="0.01 0.048 0.1255"/>
 <geom class="collision" size="0.06" pos="0.01 0.056 0.1755"/>
 <geom class="collision" size="0.06" pos="-0.01 0.023 0.0855"/>
 <geom class="collision" size="0.055" pos="-0.01 0.048 0.1255"/>
 <geom class="collision" size="0.06" pos="-0.01 0.056 0.1755"/>
 <geom class="collision" size="0.075" pos="0 0.045 0.2155"/>
 <geom class="collision" size="0.075" pos="0 0 0.2155"/>
 <inertial mass="10" pos="0 0 0" diaginertia="0.1 0.1 0.1"/>

 <body name="left_link_4" pos="0 0.1593 0.0875" euler="-1.57 0 0">
 <joint name="left_joint_4" pos="0 0 0" axis="0 0 1" range="-3.14159 3.14159" damping="55"/>
 <geom class="visual" type="mesh" mesh="link4" material="green_material"/>
 <!-- Link 4 collision geoms -->
 <geom class="collision" type="capsule" size="0.05" fromto="0 0 -0.1 0 0 0.1"/>
 <geom class="collision" type="sphere" size="0.06" pos="0 0 0.05"/>
 <geom class="collision" type="sphere" size="0.06" pos="0 0 -0.05"/>
 <geom class="collision" type="box" size="0.05 0.05 0.03" pos="0 0.04 0.08"/>
 <geom class="collision" type="box" size="0.05 0.05 0.03" pos="0 -0.04 0.08"/>
 <inertial mass="10" pos="0 0 0" diaginertia="0.1 0.1 0.1"/>

 <body name="left_link_5" pos="0 0.03185 0.16105" euler="0.50951 0 1.57">
 <joint name="left_joint_5" pos="0 0 0" axis="0 0 1" range="-3.14159 3.14159" damping="55"/>
 <geom class="visual" type="mesh" mesh="link5" material="green_material"/>
 <!-- Link 5 collision geoms -->
 <geom class="collision" type="capsule" size="0.04" fromto="0 -0.05 0 0 0.05 0"/>
 <geom class="collision" type="box" size="0.06 0.06 0.04" pos="0 0 0"/>
 <geom class="collision" type="sphere" size="0.05" pos="0 0.04 0.03"/>
 <geom class="collision" type="sphere" size="0.05" pos="0 -0.04 0.03"/>
 <geom class="collision" type="box" size="0.04 0.04 0.02" pos="0 0 0.06"/>
 <inertial mass="10" pos="0 0 0" diaginertia="0.1 0.1 0.1"/>
 
 <body name="left_end_effector" pos="0 -0.1227 0.0654" quat="0.707105 0.707108 0 0">
 <joint name="left_joint_6" pos="0 0 0" axis="0 0 -1" range="-3.14159 3.14159" damping="55"/>
 <geom class="visual" type="mesh" mesh="end_effector" material="green_material"/>
 <!-- End effector collision geoms -->
 <geom class="collision" type="box" size="0.05 0.05 0.05" pos="0 0 0"/>
 <geom class="collision" type="sphere" size="0.04" pos="0 0.04 0.04"/>
 <geom class="collision" type="sphere" size="0.04" pos="0 -0.04 0.04"/>
 <geom class="collision" type="cylinder" size="0.03 0.02" pos="0 0 -0.03" euler="1.5708 0 0"/>
 <site name="attachment_site" pos="0 0 0" size="0.01" type="sphere" rgba="0 0 1 1"/>
 <inertial mass="10" pos="0 0 0" diaginertia="0.1 0.1 0.1"/>
 </body>
 </body>
 </body>
 </body>
 </body>
 </body>
 </body>
 </worldbody>

 <actuator>
 <motor name="left_turret" joint="left_joint_1"/>
 <motor name="left_shoulder" joint="left_joint_2"/>
 <motor name="left_elbow" joint="left_joint_3"/>
 <motor name="left_wrist_1" joint="left_joint_4"/>
 <motor name="left_wrist_2" joint="left_joint_5"/>
 <motor name="left_wrist_3" joint="left_joint_6"/>
 </actuator>
</mujoco> -->
