<mujoco model="heal_single_arm">
   <option gravity="0 0 -9.81" />
   <compiler angle="radian" inertiafromgeom="false" discardvisual="false" meshdir="../heal_meshes/" />
   <statistic center="0.3 0 0.4" extent="1.5"/>
   
   <asset>
      <!-- Textures -->
      <texture type="skybox" builtin="gradient" rgb1="0.3 0.5 0.7" rgb2="0 0 0" width="512" height="3072"/>
      <texture type="2d" name="groundplane" builtin="checker" mark="edge" rgb1="0.2 0.3 0.4" rgb2="0.1 0.2 0.3"
               markrgb="0.8 0.8 0.8" width="300" height="300"/>
      <material name="groundplane" texture="groundplane" texuniform="true" texrepeat="5 5" reflectance="0.2"/>
      
      <!-- Robot Meshes -->
      <mesh name="base_link" file="base_link.STL"/>
      <mesh name="link1" file="link_1.STL"/>
      <mesh name="link2" file="link_2.STL"/>
      <mesh name="link3" file="link_3.STL"/>
      <mesh name="link4" file="link_4.STL"/>
      <mesh name="link5" file="link_5.STL"/>
      <mesh name="end_effector" file="end_effector.STL"/>

      <!-- Visual Materials -->
      <material name="green_material" rgba="0.2 0.8 0.2 1"/> <!-- Match Kinova Green -->
      <material name="grey_material" rgba="0.75294 0.75294 0.75294 1"/> <!-- Collision Material -->
   </asset>

   <worldbody>
      <light pos="0 0 1.5" dir="0 0 -1" directional="true"/>
      <geom name="floor" size="0 0 0.05" type="plane" material="groundplane"/>
      <camera name="scene_3d_view" pos="1 1 1" zaxis="-0 -1 -1"/>

      <!-- Left Arm -->
      <body name="left_base_link" pos="0.2 0 0" euler="0 0 1.5708">
         <geom type="mesh" mesh="base_link" material="grey_material"/>

         <body name="left_link_1" pos="0 0 0.171">
            <joint name="left_joint_1" pos="0 0 0" axis="0 0 1" range="-3.14159 3.14159" damping="55" frictionloss="0.1" actuatorfrcrange="-10000 10000"/>
            <geom type="mesh" mesh="link1" material="green_material" contype="0" conaffinity="0"/>

            <body name="left_link_2" pos="0 0.0875 0.1498" quat="0.707105 0.707108 0 0">
               <joint name="left_joint_2" pos="0 0 0" axis="0 0 -1" range="-3.14159 3.14159" damping="55" frictionloss="0.1" actuatorfrcrange="-10000 10000"/>
               <geom type="mesh" mesh="link2" material="green_material" contype="0" conaffinity="0"/>

               <body name="left_link_3" pos="0 0.3 0" euler="0 0 -1.57">
                  <joint name="left_joint_3" pos="0 0 0" axis="0 0 1" range="-3.14159 3.14159" damping="55" frictionloss="0.1" actuatorfrcrange="-10000 10000"/>
                  <geom type="mesh" mesh="link3" material="green_material" contype="0" conaffinity="0"/>

                  <body name="left_link_4" pos="0 0.1593 0.0875" euler="-1.57 0 0">
                     <joint name="left_joint_4" pos="0 0 0" axis="0 0 1" range="-3.14159 3.14159" damping="55" frictionloss="0.1" actuatorfrcrange="-10000 10000"/>
                     <geom type="mesh" mesh="link4" material="green_material" contype="0" conaffinity="0"/>

                     <body name="left_link_5" pos="0 0.03185 0.16105" euler="0.50951 0 1.57">
                        <joint name="left_joint_5" pos="0 0 0" axis="0 0 1" range="-3.14159 3.14159" damping="55" frictionloss="0.1" actuatorfrcrange="-10000 10000"/>
                        <geom type="mesh" mesh="link5" material="green_material" contype="0" conaffinity="0"/>

                        <body name="left_end_effector" pos="0 -0.1227 0.0654" quat="0.707105 0.707108 0 0">
                           <joint name="left_joint_6" pos="0 0 0" axis="0 0 -1" range="-3.14159 3.14159" damping="55" frictionloss="0.1" actuatorfrcrange="-10000 10000"/>
                           <geom type="mesh" mesh="end_effector" material="green_material" contype="0" conaffinity="0"/>
                        </body>
                     </body>
                  </body>
               </body>
            </body>
         </body>
      </body>
   </worldbody>

   <actuator>
      <motor name="left_turret" joint="left_joint_1"/>
      <motor name="left_shoulder" joint="left_joint_2"/>
      <motor name="left_elbow" joint="left_joint_3"/>
      <motor name="left_wrist_1" joint="left_joint_4"/>
      <motor name="left_wrist_2" joint="left_joint_5"/>
      <motor name="left_wrist_3" joint="left_joint_6"/>
   </actuator>
</mujoco>
